Workbook

Sheet Summary
A1: PerfectPPI — COGS and gross margin by product (base case)
A2: All figures link to the product sheets; change Inputs to re-run. Ordered by how much of the number comes from the repo versus assumptions — read the notes column.
A4: Product | B4: Revenue / unit | C4: COGS / unit | D4: Gross profit / unit | E4: Gross margin | F4: What drives it
A5: Consumer PPI — self-inspection (personal) | B5: ='PPI COGS'!B18 -> 19 | C5: ='PPI COGS'!B16 -> 1.9425281 | D5: =B5-C5 -> 17.057472 | E5: =IF(B5=0,0,D5/B5) -> 0.89776168 | F5: Infrastructure only: two Gemini 2.5 Flash calls on ≤16 photos, R2 storage, platform share, Stripe. Cents per unit — pricing is a product decision, not a cost one.
A6: Consumer PPI — general technician | B6: ='PPI COGS'!C18 -> 149 | C6: ='PPI COGS'!C16 -> 123.08753 | D6: =B6-C6 -> 25.912472 | E6: =IF(B6=0,0,D6/B6) -> 0.17390921 | F6: Technician payout + travel ≈ 85–90% of COGS. Margin moves with payout structure, routing density and price; not with AI or storage.
A7: Consumer PPI — certified technician | B7: ='PPI COGS'!D18 -> 229 | C7: ='PPI COGS'!D16 -> 166.60753 | D7: =B7-C7 -> 62.392472 | E7: =IF(B7=0,0,D7/B7) -> 0.27245621 | F7: Same structure with the certified-tech payout premium.
A8: Consumer PPI — dents & tires scope | B8: ='PPI COGS'!E18 -> 79 | C8: ='PPI COGS'!E16 -> 79.857528 | D8: =B8-C8 -> -0.85752806 | E8: =IF(B8=0,0,D8/B8) -> -0.010854786 | F8: Shorter scope, lower payout; feeds the dents/tires coverage product.
A9: VSC — Basic $599 (1 yr) | B9: ='Warranty COGS'!F5 -> 599 | C9: ='Warranty COGS'!O5 -> 347.621 | D9: =B9-C9 -> 251.379 | E9: =IF(B9=0,0,D9/B9) -> 0.41966444 | F9: Underwriting cost under the structure selected on Inputs. Launch-blocked until obligor/licensing questions in docs/compliance/open-questions.md are closed.
A10: VSC — Standard $999 (2 yr) | B10: ='Warranty COGS'!F6 -> 999 | C10: ='Warranty COGS'!O6 -> 579.221 | D10: =B10-C10 -> 419.779 | E10: =IF(B10=0,0,D10/B10) -> 0.4201992 | F10: Same.
A11: VSC — Premium $1,499 (3 yr) | B11: ='Warranty COGS'!F7 -> 1499 | C11: ='Warranty COGS'!O7 -> 868.721 | D11: =B11-C11 -> 630.279 | E11: =IF(B11=0,0,D11/B11) -> 0.42046631 | F11: Same.
A12: Bundle — certified PPI + Standard VSC | B12: =B7+B10 -> 1228 | C12: =C7+C10 -> 745.82853 | D12: =B12-C12 -> 482.17147 | E12: =IF(B12=0,0,D12/B12) -> 0.39264778 | F12: The inspection is the underwriting gate for the contract; sold together the blended margin is dominated by the VSC.
A13: Shop pre-estimate — option A, per inspection | B13: ='Shop Pre-Estimate COGS'!B13 -> 4 | C13: ='Shop Pre-Estimate COGS'!B11 -> 0.52671343 | D13: =B13-C13 -> 3.4732866 | E13: =IF(B13=0,0,D13/B13) -> 0.86832164 | F13: No labor. COGS is AI tokens + storage + platform share; 90%+ margin at any sane price. Sales and onboarding are the real cost, outside COGS.
A14: Shop pre-estimate — option B, subscription (per inspection equivalent) | B14: ='Shop Pre-Estimate COGS'!C13 -> 2.4916667 | C14: ='Shop Pre-Estimate COGS'!C11 -> 0.48297176 | D14: =B14-C14 -> 2.0086949 | E14: =IF(B14=0,0,D14/B14) -> 0.80616518 | F14: Revenue per inspection = subscription ÷ inspections per shop-month; margin falls as a shop uses it more, which is the point of the subscription.
A16: Sensitivity — general-technician PPI gross margin vs. technician payout and price
A17: Technician payout \ Price | B17: 129 | C17: 149 | D17: 169 | E17: 199 | F17: 229
A18: 80 | B18: =1-('PPI COGS'!C24+Inputs!$B$40+$A18+Inputs!$B$46*($A18+Inputs!$B$40)+B$17*Inputs!$B$32+Inputs!$B$33)/B$17 -> 0.17009668 | C18: =1-('PPI COGS'!C24+Inputs!$B$40+$A18+Inputs!$B$46*($A18+Inputs!$B$40)+C$17*Inputs!$B$32+Inputs!$B$33)/C$17 -> 0.27760048 | D18: =1-('PPI COGS'!C24+Inputs!$B$40+$A18+Inputs!$B$46*($A18+Inputs!$B$40)+D$17*Inputs!$B$32+Inputs!$B$33)/D$17 -> 0.3596596 | E18: =1-('PPI COGS'!C24+Inputs!$B$40+$A18+Inputs!$B$46*($A18+Inputs!$B$40)+E$17*Inputs!$B$32+Inputs!$B$33)/E$17 -> 0.45182147 | F18: =1-('PPI COGS'!C24+Inputs!$B$40+$A18+Inputs!$B$46*($A18+Inputs!$B$40)+F$17*Inputs!$B$32+Inputs!$B$33)/F$17 -> 0.51983612
A19: 95 | B19: =1-('PPI COGS'!C24+Inputs!$B$40+$A19+Inputs!$B$46*($A19+Inputs!$B$40)+B$17*Inputs!$B$32+Inputs!$B$33)/B$17 -> 0.05032924 | C19: =1-('PPI COGS'!C24+Inputs!$B$40+$A19+Inputs!$B$46*($A19+Inputs!$B$40)+C$17*Inputs!$B$32+Inputs!$B$33)/C$17 -> 0.17390921 | D19: =1-('PPI COGS'!C24+Inputs!$B$40+$A19+Inputs!$B$46*($A19+Inputs!$B$40)+D$17*Inputs!$B$32+Inputs!$B$33)/D$17 -> 0.26823948 | E19: =1-('PPI COGS'!C24+Inputs!$B$40+$A19+Inputs!$B$46*($A19+Inputs!$B$40)+E$17*Inputs!$B$32+Inputs!$B$33)/E$17 -> 0.37418328 | F19: =1-('PPI COGS'!C24+Inputs!$B$40+$A19+Inputs!$B$46*($A19+Inputs!$B$40)+F$17*Inputs!$B$32+Inputs!$B$33)/F$17 -> 0.45236887
A20: 110 | B20: =1-('PPI COGS'!C24+Inputs!$B$40+$A20+Inputs!$B$46*($A20+Inputs!$B$40)+B$17*Inputs!$B$32+Inputs!$B$33)/B$17 -> -0.069438202 | C20: =1-('PPI COGS'!C24+Inputs!$B$40+$A20+Inputs!$B$46*($A20+Inputs!$B$40)+C$17*Inputs!$B$32+Inputs!$B$33)/C$17 -> 0.070217933 | D20: =1-('PPI COGS'!C24+Inputs!$B$40+$A20+Inputs!$B$46*($A20+Inputs!$B$40)+D$17*Inputs!$B$32+Inputs!$B$33)/D$17 -> 0.17681936 | E20: =1-('PPI COGS'!C24+Inputs!$B$40+$A20+Inputs!$B$46*($A20+Inputs!$B$40)+E$17*Inputs!$B$32+Inputs!$B$33)/E$17 -> 0.29654509 | F20: =1-('PPI COGS'!C24+Inputs!$B$40+$A20+Inputs!$B$46*($A20+Inputs!$B$40)+F$17*Inputs!$B$32+Inputs!$B$33)/F$17 -> 0.38490162
A21: 125 | B21: =1-('PPI COGS'!C24+Inputs!$B$40+$A21+Inputs!$B$46*($A21+Inputs!$B$40)+B$17*Inputs!$B$32+Inputs!$B$33)/B$17 -> -0.18920564 | C21: =1-('PPI COGS'!C24+Inputs!$B$40+$A21+Inputs!$B$46*($A21+Inputs!$B$40)+C$17*Inputs!$B$32+Inputs!$B$33)/C$17 -> -0.033473343 | D21: =1-('PPI COGS'!C24+Inputs!$B$40+$A21+Inputs!$B$46*($A21+Inputs!$B$40)+D$17*Inputs!$B$32+Inputs!$B$33)/D$17 -> 0.085399242 | E21: =1-('PPI COGS'!C24+Inputs!$B$40+$A21+Inputs!$B$46*($A21+Inputs!$B$40)+E$17*Inputs!$B$32+Inputs!$B$33)/E$17 -> 0.21890689 | F21: =1-('PPI COGS'!C24+Inputs!$B$40+$A21+Inputs!$B$46*($A21+Inputs!$B$40)+F$17*Inputs!$B$32+Inputs!$B$33)/F$17 -> 0.31743438
A22: 140 | B22: =1-('PPI COGS'!C24+Inputs!$B$40+$A22+Inputs!$B$46*($A22+Inputs!$B$40)+B$17*Inputs!$B$32+Inputs!$B$33)/B$17 -> -0.30897309 | C22: =1-('PPI COGS'!C24+Inputs!$B$40+$A22+Inputs!$B$46*($A22+Inputs!$B$40)+C$17*Inputs!$B$32+Inputs!$B$33)/C$17 -> -0.13716462 | D22: =1-('PPI COGS'!C24+Inputs!$B$40+$A22+Inputs!$B$46*($A22+Inputs!$B$40)+D$17*Inputs!$B$32+Inputs!$B$33)/D$17 -> -0.0060208761 | E22: =1-('PPI COGS'!C24+Inputs!$B$40+$A22+Inputs!$B$46*($A22+Inputs!$B$40)+E$17*Inputs!$B$32+Inputs!$B$33)/E$17 -> 0.1412687 | F22: =1-('PPI COGS'!C24+Inputs!$B$40+$A22+Inputs!$B$46*($A22+Inputs!$B$40)+F$17*Inputs!$B$32+Inputs!$B$33)/F$17 -> 0.24996713
A24: Not COGS (kept out on purpose): salaries, sales & marketing, customer acquisition, technician recruiting, app store fees on digital-only sales (Apple takes 15–30% if the self-inspection is sold as an in-app purchase — decide the billing path before pricing it), R&D, and the fixed platform cost beyond its per-unit allocation.

Sheet Inputs
A1: PerfectPPI — COGS model inputs
A2: Blue cells are inputs; yellow-filled blue cells are the assumptions that most need your own numbers. Every other sheet is formulas. Sources: 'Repo:' = read from this repository; 'List price' = vendor public pricing at time of writing — verify against your invoices; 'Assumption' = a planning estimate to replace.
A4: Volume and shared platform (allocation base) | B4: Value | C4: Unit | D4: Source / note
A5: Consumer PPI inspections per month (planning volume) | B5: 200 | C5: inspections / month | D5: Assumption — used only to spread fixed platform cost per unit. Raise it and per-unit hosting falls.
A6: Shop pre-estimate inspections per month (planning volume) | B6: 2400 | C6: inspections / month | D6: Assumption — 20 shops × 120 inspections/month. Shares the same platform allocation.
A7: Fixed platform cost | B7: 145 | C7: $ / month | D7: List price: Supabase Pro $25 + small compute add-on ~$60, Vercel Pro $20, Apple Developer $99/yr (~$8/mo), monitoring/alerts ~$32. Verify against invoices. Payroll and marketing are NOT in COGS.
A8: Loaded cost per support ticket | B8: 6 | C8: $ / ticket | D8: Assumption — ~15 min at $24/hr loaded.
A9: Support tickets per consumer inspection | B9: 0.15 | C9: tickets / inspection | D9: Assumption.
A10: Support tickets per shop inspection | B10: 0.02 | C10: tickets / inspection | D10: Assumption — shops are trained once; per-inspection contact is rare.
A12: Google Gemini 2.5 Flash (src/lib/ai/gemini.ts, default model) | B12: Value | C12: Unit | D12: Source / note
A13: Input price | B13: 0.3 | C13: $ / 1M tokens | D13: List price, Gemini 2.5 Flash paid tier (text/image/video input). Verify at ai.google.dev/pricing.
A14: Output price | B14: 2.5 | C14: $ / 1M tokens | D14: List price, Gemini 2.5 Flash paid tier.
A15: Tokens per photo sent to the model | B15: 6192 | C15: tokens / photo | D15: Gemini image tokenisation: images ≤384px = 258 tokens; larger images are tiled into 768px crops at 258 tokens each. A 12MP (4032×3024) photo = 6×4 tiles = 6,192 tokens. Downscaling photos to ≤768px before the call cuts this to 258.
A16: Photos sent to the model per consumer inspection | B16: 16 | C16: photos | D16: Repo: INSPECTION_PHOTO_LIMIT default 16 (src/features/outputs/inspection-photos.ts).
A17: Text prompt + answers per model call | B17: 9000 | C17: tokens / call | D17: Repo: standardized-output prompt ≈13k chars and VSC prompt ≈5k chars (src/lib/ai/prompts) plus 76 inspection answers (src/features/ppi/constants.ts). Estimate.
A18: Structured output per model call | B18: 4000 | C18: tokens / call | D18: Assumption — JSON report / coverage determination.
A19: Model calls per consumer inspection | B19: 2 | C19: calls | D19: Repo: standardized report + VSC determination, both in one pipeline run (src/features/outputs/pipeline.ts). Photos are counted on both calls (conservative).
A20: VIN photo read | B20: 2000 | C20: tokens / inspection | D20: Repo: VIN image reading via Gemini (VIN scan routes). Small.
A22: Cloudflare R2 storage (src/lib/storage/r2.ts) | B22: Value | C22: Unit | D22: Source / note
A23: Storage | B23: 0.015 | C23: $ / GB-month | D23: List price. Egress is free on R2.
A24: Class A operations (writes) | B24: 4.5 | C24: $ / 1M ops | D24: List price.
A25: Photos stored per consumer inspection | B25: 30 | C25: photos | D25: Repo: 9 photo-required prompts + optional answer photos + OBD screenshots; 30 is an average assumption.
A26: Average stored photo size | B26: 3 | C26: MB / photo | D26: Assumption — iPhone JPEG/HEIC after client-side compression.
A27: Generated artifacts per inspection | B27: 2 | C27: MB / inspection | D27: Repo: two PDFs (standardized report, VSC determination) + derivatives.
A28: Retention of inspection media | B28: 36 | C28: months | D28: Assumption — docs/compliance/retention-schedule.md ties inspection media to the account; a standalone period still needs approval.
A29: R2 write operations per inspection (lifetime) | B29: 400 | C29: operations | D29: Assumption — uploads, derivatives, moves out of quarantine.
A31: Payments and e-signature | B31: Value | C31: Unit | D31: Source / note
A32: Stripe card fee (percentage) | B32: 0.029 | C32: % of transaction | D32: List price, US domestic cards (src/lib/stripe).
A33: Stripe card fee (fixed) | B33: 0.3 | C33: $ / transaction | D33: List price.
A34: E-signature cost per signed contract | B34: 0.5 | C34: $ / contract | D34: Assumption — DocuSeal cloud plan spread over contracts (src/lib/docuseal). Verify plan at docuseal.com/pricing.
A36: Technician-performed consumer PPI (ppi_type general_tech / certified_tech; scope complete / dents_tires) | B36: Value | C36: Unit | D36: Source / note
A37: Technician payout — general tech, complete scope | B37: 95 | C37: $ / inspection | D37: Assumption — 1099 mobile inspector, ~75–90 min on site. Market comparables for mobile PPI labor are roughly $80–$120. THE dominant COGS line.
A38: Technician payout — certified tech, complete scope | B38: 135 | C38: $ / inspection | D38: Assumption — ASE-certified / shop technician premium.
A39: Technician payout — dents & tires scope | B39: 55 | C39: $ / inspection | D39: Assumption — ~30 min scope (inspection_scope 'dents_tires', src/features/warranty/dents-tires-coverage.ts).
A40: Travel reimbursement per technician inspection | B40: 12 | C40: $ / inspection | D40: Assumption — mileage/fuel for a mobile visit.
A41: OBD adapter cost | B41: 99 | C41: $ / unit | D41: OBDLink CX retail (docs/OBD Tool.md).
A42: Inspections per adapter over its life | B42: 300 | C42: inspections / unit | D42: Assumption.
A43: Share of technician inspections on company-provided adapters | B43: 0.5 | C43: % | D43: Assumption — the rest use the technician's own adapter.
A44: General liability / E&O allocation | B44: 4 | C44: $ / technician inspection | D44: Assumption — annual premium ÷ expected technician inspections.
A45: Human QA review allocation | B45: 3 | C45: $ / technician inspection | D45: Assumption — ~10 min at $18/hr on the share of reports spot-checked.
...

Sheet PPI COGS
A1: Consumer pre-purchase inspection — COGS per inspection
A2: One column per delivery mode in the repo (ppi_type personal / general_tech / certified_tech, and the dents_tires scope). Prices are the assumptions on Inputs; everything else is a formula.
A4: Component ($ per inspection) | B4: Self-inspection (personal) | C4: General tech (complete) | D4: Certified tech (complete) | E4: Tech — dents & tires
A5: Technician payout | B5: 0 | C5: =Inputs!$B$37 -> 95 | D5: =Inputs!$B$38 -> 135 | E5: =Inputs!$B$39 -> 55
A6: Travel reimbursement | B6: 0 | C6: =Inputs!$B$40 -> 12 | D6: =Inputs!$B$40 -> 12 | E6: =Inputs!$B$40 -> 12
A7: OBD adapter amortisation (company-provided share) | B7: 0 | C7: =Inputs!$B$41/Inputs!$B$42*Inputs!$B$43 -> 0.165 | D7: =Inputs!$B$41/Inputs!$B$42*Inputs!$B$43 -> 0.165 | E7: =Inputs!$B$41/Inputs!$B$42*Inputs!$B$43 -> 0.165
A8: AI report + VSC determination (Gemini) | B8: =Inputs!$B$19*((Inputs!$B$17+Inputs!$B$16*Inputs!$B$15)*Inputs!$B$13/1000000+Inputs!$B$18*Inputs!$B$14/1000000)+Inputs!$B$20*Inputs!$B$13/1000000 -> 0.0854432 | C8: =Inputs!$B$19*((Inputs!$B$17+Inputs!$B$16*Inputs!$B$15)*Inputs!$B$13/1000000+Inputs!$B$18*Inputs!$B$14/1000000)+Inputs!$B$20*Inputs!$B$13/1000000 -> 0.0854432 | D8: =Inputs!$B$19*((Inputs!$B$17+Inputs!$B$16*Inputs!$B$15)*Inputs!$B$13/1000000+Inputs!$B$18*Inputs!$B$14/1000000)+Inputs!$B$20*Inputs!$B$13/1000000 -> 0.0854432 | E8: =Inputs!$B$19*((Inputs!$B$17+Inputs!$B$16*Inputs!$B$15)*Inputs!$B$13/1000000+Inputs!$B$18*Inputs!$B$14/1000000)+Inputs!$B$20*Inputs!$B$13/1000000 -> 0.0854432
A9: Photo + PDF storage over retention (R2) | B9: =((Inputs!$B$25*Inputs!$B$26+Inputs!$B$27)/1024)*Inputs!$B$23*Inputs!$B$28+Inputs!$B$29/1000000*Inputs!$B$24 -> 0.050315625 | C9: =((Inputs!$B$25*Inputs!$B$26+Inputs!$B$27)/1024)*Inputs!$B$23*Inputs!$B$28+Inputs!$B$29/1000000*Inputs!$B$24 -> 0.050315625 | D9: =((Inputs!$B$25*Inputs!$B$26+Inputs!$B$27)/1024)*Inputs!$B$23*Inputs!$B$28+Inputs!$B$29/1000000*Inputs!$B$24 -> 0.050315625 | E9: =((Inputs!$B$25*Inputs!$B$26+Inputs!$B$27)/1024)*Inputs!$B$23*Inputs!$B$28+Inputs!$B$29/1000000*Inputs!$B$24 -> 0.050315625
A10: Shared platform allocation (Supabase, Vercel, Apple, monitoring) | B10: =Inputs!$B$7/(Inputs!$B$5+Inputs!$B$6) -> 0.055769231 | C10: =Inputs!$B$7/(Inputs!$B$5+Inputs!$B$6) -> 0.055769231 | D10: =Inputs!$B$7/(Inputs!$B$5+Inputs!$B$6) -> 0.055769231 | E10: =Inputs!$B$7/(Inputs!$B$5+Inputs!$B$6) -> 0.055769231
A11: Customer support | B11: =Inputs!$B$9*Inputs!$B$8 -> 0.9 | C11: =Inputs!$B$9*Inputs!$B$8 -> 0.9 | D11: =Inputs!$B$9*Inputs!$B$8 -> 0.9 | E11: =Inputs!$B$9*Inputs!$B$8 -> 0.9
A12: Human QA review of the report | B12: 0 | C12: =Inputs!$B$45 -> 3 | D12: =Inputs!$B$45 -> 3 | E12: =Inputs!$B$45 -> 3
A13: Liability / E&O allocation | B13: 0 | C13: =Inputs!$B$44 -> 4 | D13: =Inputs!$B$44 -> 4 | E13: =Inputs!$B$44 -> 4
A14: Refund / re-inspection allowance | B14: 0 | C14: =Inputs!$B$46*(C5+C6) -> 3.21 | D14: =Inputs!$B$46*(D5+D6) -> 4.41 | E14: =Inputs!$B$46*(E5+E6) -> 2.01
A15: Payment processing (Stripe) | B15: =IF(Inputs!$B$49>0,Inputs!$B$49*Inputs!$B$32+Inputs!$B$33,0) -> 0.851 | C15: =IF(Inputs!$B$50>0,Inputs!$B$50*Inputs!$B$32+Inputs!$B$33,0) -> 4.621 | D15: =IF(Inputs!$B$51>0,Inputs!$B$51*Inputs!$B$32+Inputs!$B$33,0) -> 6.941 | E15: =IF(Inputs!$B$52>0,Inputs!$B$52*Inputs!$B$32+Inputs!$B$33,0) -> 2.591
A16: Total COGS per inspection | B16: =SUM(B5:B15) -> 1.9425281 | C16: =SUM(C5:C15) -> 123.08753 | D16: =SUM(D5:D15) -> 166.60753 | E16: =SUM(E5:E15) -> 79.857528
A18: Retail price (Inputs) | B18: =Inputs!$B$49 -> 19 | C18: =Inputs!$B$50 -> 149 | D18: =Inputs!$B$51 -> 229 | E18: =Inputs!$B$52 -> 79
A19: Gross profit per inspection | B19: =B18-B16 -> 17.057472 | C19: =C18-C16 -> 25.912472 | D19: =D18-D16 -> 62.392472 | E19: =E18-E16 -> -0.85752806
A20: Gross margin | B20: =IF(B18=0,0,B19/B18) -> 0.89776168 | C20: =IF(C18=0,0,C19/C18) -> 0.17390921 | D20: =IF(D18=0,0,D19/D18) -> 0.27245621 | E20: =IF(E18=0,0,E19/E18) -> -0.010854786
A22: of which: infrastructure only (AI + storage + hosting) | B22: =B8+B9+B10 -> 0.19152806 | C22: =C8+C9+C10 -> 0.19152806 | D22: =D8+D9+D10 -> 0.19152806 | E22: =E8+E9+E10 -> 0.19152806
A23: Technician payout + travel as a share of COGS | B23: =IF(B16=0,0,(B5+B6)/B16) -> 0 | C23: =IF(C16=0,0,(C5+C6)/C16) -> 0.8693001 | D23: =IF(D16=0,0,(D5+D6)/D16) -> 0.88231307 | E23: =IF(E16=0,0,(E5+E6)/E16) -> 0.83899416
A24: Helper: overhead excl. payout, travel, redo and payment (used by Summary sensitivity) | B24: =B7+B8+B9+B10+B11+B12+B13 -> 1.0915281 | C24: =C7+C8+C9+C10+C11+C12+C13 -> 8.2565281 | D24: =D7+D8+D9+D10+D11+D12+D13 -> 8.2565281 | E24: =E7+E8+E9+E10+E11+E12+E13 -> 8.2565281
A26: Reading it: the self-inspection costs cents to deliver, so it can be free or a low-priced entry product. For technician-performed inspections the payout and travel are ~85–90% of COGS; AI, storage and hosting together are well under $1. Improving margin means routing density (travel), payout structure, or price — not infrastructure.

Sheet Warranty COGS
A1: Vehicle service contract (warranty) — COGS per contract
A2: Plan names, prices, terms and deductibles are exactly what src/features/warranty/actions.ts (buildPlansFromCoverage) offers. Underwriting cost follows the structure selected on Inputs: 1 = a licensed obligor sells PerfectPPI the contract at a wholesale price (PerfectPPI is the seller); 2 = PerfectPPI is the obligor and carries expected claims, claims administration and CLIP. Selling costs (commissions, marketing) are not COGS.
A4: Plan (repo) | B4: Eligibility | C4: Term (yrs) | D4: Term (mi) | E4: Deductible | F4: Retail price | G4: Structure 1: wholesale cost | H4: Structure 2: expected claims | I4: Structure 2: claims admin | J4: Structure 2: CLIP | K4: Underwriting COGS (selected structure) | L4: E-signature | M4: Payment processing | N4: Premium / sales tax | O4: Total COGS | P4: Gross profit | Q4: Gross margin
A5: Basic Coverage | B5: full | C5: 1 | D5: 12000 | E5: 100 | F5: 599 | G5: =F5*Inputs!$B$56 -> 329.45 | H5: =F5*Inputs!$B$57 -> 359.4 | I5: =Inputs!$B$58 -> 35 | J5: =F5*Inputs!$B$59 -> 47.92 | K5: =IF(Inputs!$B$55=1,G5,H5+I5+J5) -> 329.45 | L5: =Inputs!$B$34 -> 0.5 | M5: =F5*Inputs!$B$32+Inputs!$B$33 -> 17.671 | N5: =F5*Inputs!$B$60 -> 0 | O5: =K5+L5+M5+N5 -> 347.621 | P5: =F5-O5 -> 251.379 | Q5: =IF(F5=0,0,P5/F5) -> 0.41966444
A6: Standard Coverage | B6: full | C6: 2 | D6: 24000 | E6: 75 | F6: 999 | G6: =F6*Inputs!$B$56 -> 549.45 | H6: =F6*Inputs!$B$57 -> 599.4 | I6: =Inputs!$B$58 -> 35 | J6: =F6*Inputs!$B$59 -> 79.92 | K6: =IF(Inputs!$B$55=1,G6,H6+I6+J6) -> 549.45 | L6: =Inputs!$B$34 -> 0.5 | M6: =F6*Inputs!$B$32+Inputs!$B$33 -> 29.271 | N6: =F6*Inputs!$B$60 -> 0 | O6: =K6+L6+M6+N6 -> 579.221 | P6: =F6-O6 -> 419.779 | Q6: =IF(F6=0,0,P6/F6) -> 0.4201992
A7: Premium Coverage | B7: full | C7: 3 | D7: 36000 | E7: 50 | F7: 1499 | G7: =F7*Inputs!$B$56 -> 824.45 | H7: =F7*Inputs!$B$57 -> 899.4 | I7: =Inputs!$B$58 -> 35 | J7: =F7*Inputs!$B$59 -> 119.92 | K7: =IF(Inputs!$B$55=1,G7,H7+I7+J7) -> 824.45 | L7: =Inputs!$B$34 -> 0.5 | M7: =F7*Inputs!$B$32+Inputs!$B$33 -> 43.771 | N7: =F7*Inputs!$B$60 -> 0 | O7: =K7+L7+M7+N7 -> 868.721 | P7: =F7-O7 -> 630.279 | Q7: =IF(F7=0,0,P7/F7) -> 0.42046631
A8: Conditional Coverage | B8: conditional | C8: 1 | D8: 12000 | E8: 100 | F8: 799 | G8: =F8*Inputs!$B$56 -> 439.45 | H8: =F8*Inputs!$B$57 -> 479.4 | I8: =Inputs!$B$58 -> 35 | J8: =F8*Inputs!$B$59 -> 63.92 | K8: =IF(Inputs!$B$55=1,G8,H8+I8+J8) -> 439.45 | L8: =Inputs!$B$34 -> 0.5 | M8: =F8*Inputs!$B$32+Inputs!$B$33 -> 23.471 | N8: =F8*Inputs!$B$60 -> 0 | O8: =K8+L8+M8+N8 -> 463.421 | P8: =F8-O8 -> 335.579 | Q8: =IF(F8=0,0,P8/F8) -> 0.41999875
A9: Extended Conditional | B9: conditional | C9: 2 | D9: 24000 | E9: 100 | F9: 1399 | G9: =F9*Inputs!$B$56 -> 769.45 | H9: =F9*Inputs!$B$57 -> 839.4 | I9: =Inputs!$B$58 -> 35 | J9: =F9*Inputs!$B$59 -> 111.92 | K9: =IF(Inputs!$B$55=1,G9,H9+I9+J9) -> 769.45 | L9: =Inputs!$B$34 -> 0.5 | M9: =F9*Inputs!$B$32+Inputs!$B$33 -> 40.871 | N9: =F9*Inputs!$B$60 -> 0 | O9: =K9+L9+M9+N9 -> 810.821 | P9: =F9-O9 -> 588.179 | Q9: =IF(F9=0,0,P9/F9) -> 0.42042816
A11: Source for columns A–F: src/features/warranty/actions.ts — Basic $599 (1 yr / 12k mi, $100 deductible), Standard $999 (2 yr / 24k, $75), Premium $1,499 (3 yr / 36k, $50); conditional-eligibility vehicles get Conditional $799 and Extended Conditional $1,399 ($100 deductible). Column B is informational.
A12: Cancellations: contracts cancel pro-rata with a matching pro-rata refund of the wholesale cost or claims reserve, so they are close to margin-neutral and are left out. Under structure 2 the cash for claims must be held in a reserve/escrow per state law — COGS here is the expected value, not the reserve requirement.
A14: Sensitivity — gross margin vs. wholesale cost share (structure 1)
A15: Wholesale % of retail | B15: Basic $599 | C15: Standard $999 | D15: Premium $1,499
A16: 0.45 | B16: =1-(F5*$A16+Inputs!$B$34+F5*Inputs!$B$32+Inputs!$B$33+F5*Inputs!$B$60)/F5 -> 0.51966444 | C16: =1-(F6*$A16+Inputs!$B$34+F6*Inputs!$B$32+Inputs!$B$33+F6*Inputs!$B$60)/F6 -> 0.5201992 | D16: =1-(F7*$A16+Inputs!$B$34+F7*Inputs!$B$32+Inputs!$B$33+F7*Inputs!$B$60)/F7 -> 0.52046631
A17: 0.5 | B17: =1-(F5*$A17+Inputs!$B$34+F5*Inputs!$B$32+Inputs!$B$33+F5*Inputs!$B$60)/F5 -> 0.46966444 | C17: =1-(F6*$A17+Inputs!$B$34+F6*Inputs!$B$32+Inputs!$B$33+F6*Inputs!$B$60)/F6 -> 0.4701992 | D17: =1-(F7*$A17+Inputs!$B$34+F7*Inputs!$B$32+Inputs!$B$33+F7*Inputs!$B$60)/F7 -> 0.47046631
A18: 0.55 | B18: =1-(F5*$A18+Inputs!$B$34+F5*Inputs!$B$32+Inputs!$B$33+F5*Inputs!$B$60)/F5 -> 0.41966444 | C18: =1-(F6*$A18+Inputs!$B$34+F6*Inputs!$B$32+Inputs!$B$33+F6*Inputs!$B$60)/F6 -> 0.4201992 | D18: =1-(F7*$A18+Inputs!$B$34+F7*Inputs!$B$32+Inputs!$B$33+F7*Inputs!$B$60)/F7 -> 0.42046631
A19: 0.6 | B19: =1-(F5*$A19+Inputs!$B$34+F5*Inputs!$B$32+Inputs!$B$33+F5*Inputs!$B$60)/F5 -> 0.36966444 | C19: =1-(F6*$A19+Inputs!$B$34+F6*Inputs!$B$32+Inputs!$B$33+F6*Inputs!$B$60)/F6 -> 0.3701992 | D19: =1-(F7*$A19+Inputs!$B$34+F7*Inputs!$B$32+Inputs!$B$33+F7*Inputs!$B$60)/F7 -> 0.37046631
A20: 0.65 | B20: =1-(F5*$A20+Inputs!$B$34+F5*Inputs!$B$32+Inputs!$B$33+F5*Inputs!$B$60)/F5 -> 0.31966444 | C20: =1-(F6*$A20+Inputs!$B$34+F6*Inputs!$B$32+Inputs!$B$33+F6*Inputs!$B$60)/F6 -> 0.3201992 | D20: =1-(F7*$A20+Inputs!$B$34+F7*Inputs!$B$32+Inputs!$B$33+F7*Inputs!$B$60)/F7 -> 0.32046631
A22: Sensitivity — gross margin vs. loss ratio (structure 2)
A23: Loss ratio (claims / retail) | B23: Basic $599 | C23: Standard $999 | D23: Premium $1,499
A24: 0.5 | B24: =1-(F5*$A24+Inputs!$B$58+F5*Inputs!$B$59+Inputs!$B$34+F5*Inputs!$B$32+Inputs!$B$33+F5*Inputs!$B$60)/F5 -> 0.33123372 | C24: =1-(F6*$A24+Inputs!$B$58+F6*Inputs!$B$59+Inputs!$B$34+F6*Inputs!$B$32+Inputs!$B$33+F6*Inputs!$B$60)/F6 -> 0.35516416 | D24: =1-(F7*$A24+Inputs!$B$58+F7*Inputs!$B$59+Inputs!$B$34+F7*Inputs!$B$32+Inputs!$B$33+F7*Inputs!$B$60)/F7 -> 0.36711741
A25: 0.55 | B25: =1-(F5*$A25+Inputs!$B$58+F5*Inputs!$B$59+Inputs!$B$34+F5*Inputs!$B$32+Inputs!$B$33+F5*Inputs!$B$60)/F5 -> 0.28123372 | C25: =1-(F6*$A25+Inputs!$B$58+F6*Inputs!$B$59+Inputs!$B$34+F6*Inputs!$B$32+Inputs!$B$33+F6*Inputs!$B$60)/F6 -> 0.30516416 | D25: =1-(F7*$A25+Inputs!$B$58+F7*Inputs!$B$59+Inputs!$B$34+F7*Inputs!$B$32+Inputs!$B$33+F7*Inputs!$B$60)/F7 -> 0.31711741
A26: 0.6 | B26: =1-(F5*$A26+Inputs!$B$58+F5*Inputs!$B$59+Inputs!$B$34+F5*Inputs!$B$32+Inputs!$B$33+F5*Inputs!$B$60)/F5 -> 0.23123372 | C26: =1-(F6*$A26+Inputs!$B$58+F6*Inputs!$B$59+Inputs!$B$34+F6*Inputs!$B$32+Inputs!$B$33+F6*Inputs!$B$60)/F6 -> 0.25516416 | D26: =1-(F7*$A26+Inputs!$B$58+F7*Inputs!$B$59+Inputs!$B$34+F7*Inputs!$B$32+Inputs!$B$33+F7*Inputs!$B$60)/F7 -> 0.26711741
A27: 0.65 | B27: =1-(F5*$A27+Inputs!$B$58+F5*Inputs!$B$59+Inputs!$B$34+F5*Inputs!$B$32+Inputs!$B$33+F5*Inputs!$B$60)/F5 -> 0.18123372 | C27: =1-(F6*$A27+Inputs!$B$58+F6*Inputs!$B$59+Inputs!$B$34+F6*Inputs!$B$32+Inputs!$B$33+F6*Inputs!$B$60)/F6 -> 0.20516416 | D27: =1-(F7*$A27+Inputs!$B$58+F7*Inputs!$B$59+Inputs!$B$34+F7*Inputs!$B$32+Inputs!$B$33+F7*Inputs!$B$60)/F7 -> 0.21711741
A28: 0.7 | B28: =1-(F5*$A28+Inputs!$B$58+F5*Inputs!$B$59+Inputs!$B$34+F5*Inputs!$B$32+Inputs!$B$33+F5*Inputs!$B$60)/F5 -> 0.13123372 | C28: =1-(F6*$A28+Inputs!$B$58+F6*Inputs!$B$59+Inputs!$B$34+F6*Inputs!$B$32+Inputs!$B$33+F6*Inputs!$B$60)/F6 -> 0.15516416 | D28: =1-(F7*$A28+Inputs!$B$58+F7*Inputs!$B$59+Inputs!$B$34+F7*Inputs!$B$32+Inputs!$B$33+F7*Inputs!$B$60)/F7 -> 0.16711741
A29: 0.75 | B29: =1-(F5*$A29+Inputs!$B$58+F5*Inputs!$B$59+Inputs!$B$34+F5*Inputs!$B$32+Inputs!$B$33+F5*Inputs!$B$60)/F5 -> 0.081233723 | C29: =1-(F6*$A29+Inputs!$B$58+F6*Inputs!$B$59+Inputs!$B$34+F6*Inputs!$B$32+Inputs!$B$33+F6*Inputs!$B$60)/F6 -> 0.10516416 | D29: =1-(F7*$A29+Inputs!$B$58+F7*Inputs!$B$59+Inputs!$B$34+F7*Inputs!$B$32+Inputs!$B$33+F7*Inputs!$B$60)/F7 -> 0.11711741

Sheet Shop Pre-Estimate COGS
A1: Shop pre-estimate inspection (Detect Auto alternative) — COGS per inspection and per shop-month
A2: The shop's own staff photograph the vehicle; PerfectPPI supplies the app, AI damage/condition detection, the estimate-ready report and storage. There is no technician payout, so COGS is almost entirely AI tokens, storage and shared platform cost. Two pricing options are shown side by side.
A4: Component ($ per inspection) | B4: Option A: per-inspection billing | C4: Option B: subscription per shop
A5: AI damage/condition detection + estimate-ready summary (Gemini) | B5: =Inputs!$B$64*((Inputs!$B$65+Inputs!$B$63*Inputs!$B$15)*Inputs!$B$13/1000000+Inputs!$B$66*Inputs!$B$14/1000000) -> 0.128856 | C5: =Inputs!$B$64*((Inputs!$B$65+Inputs!$B$63*Inputs!$B$15)*Inputs!$B$13/1000000+Inputs!$B$66*Inputs!$B$14/1000000) -> 0.128856
A6: Photo + report storage over retention (R2) | B6: =((Inputs!$B$67*Inputs!$B$26+Inputs!$B$27)/1024)*Inputs!$B$23*Inputs!$B$68+Inputs!$B$29/1000000*Inputs!$B$24 -> 0.03414375 | C6: =((Inputs!$B$67*Inputs!$B$26+Inputs!$B$27)/1024)*Inputs!$B$23*Inputs!$B$68+Inputs!$B$29/1000000*Inputs!$B$24 -> 0.03414375
A7: Shared platform allocation | B7: =Inputs!$B$7/(Inputs!$B$5+Inputs!$B$6) -> 0.055769231 | C7: =Inputs!$B$7/(Inputs!$B$5+Inputs!$B$6) -> 0.055769231
A8: Shop onboarding amortised over shop lifetime | B8: =Inputs!$B$69/(Inputs!$B$70*Inputs!$B$71) -> 0.069444444 | C8: =Inputs!$B$69/(Inputs!$B$70*Inputs!$B$71) -> 0.069444444
A9: Support | B9: =Inputs!$B$10*Inputs!$B$8 -> 0.12 | C9: =Inputs!$B$10*Inputs!$B$8 -> 0.12
A10: Payment processing (one monthly Stripe charge per shop) | B10: =(Inputs!$B$72*Inputs!$B$71*Inputs!$B$32+Inputs!$B$33)/Inputs!$B$71 -> 0.1185 | C10: =(Inputs!$B$73*Inputs!$B$32+Inputs!$B$33)/Inputs!$B$71 -> 0.074758333
A11: Total COGS per inspection | B11: =SUM(B5:B10) -> 0.52671343 | C11: =SUM(C5:C10) -> 0.48297176
A13: Revenue per inspection | B13: =Inputs!$B$72 -> 4 | C13: =Inputs!$B$73/Inputs!$B$71 -> 2.4916667
A14: Gross profit per inspection | B14: =B13-B11 -> 3.4732866 | C14: =C13-C11 -> 2.0086949
A15: Gross margin | B15: =IF(B13=0,0,B14/B13) -> 0.86832164 | C15: =IF(C13=0,0,C14/C13) -> 0.80616518
A17: Per shop per month
A18: Revenue per shop-month | B18: =B13*Inputs!$B$71 -> 480 | C18: =Inputs!$B$73 -> 299
A19: COGS per shop-month | B19: =B11*Inputs!$B$71 -> 63.205611 | C19: =C11*Inputs!$B$71 -> 57.956611
A20: Gross profit per shop-month | B20: =B18-B19 -> 416.79439 | C20: =C18-C19 -> 241.04339
A22: Competitor comparison (placeholder price on Inputs)
A23: Shop's monthly spend at the competitor's per-inspection price | B23: =Inputs!$B$74*Inputs!$B$71 -> 720 | C23: =Inputs!$B$74*Inputs!$B$71 -> 720
A24: Shop's monthly saving with PerfectPPI | B24: =B23-B18 -> 240 | C24: =C23-C18 -> 421
A25: Break-even inspections per shop-month (COGS-only, ignores fixed overhead) | B25: =IF(B14<=0,0,ROUNDUP(0/1,0)) -> 0 | C25: =IF(Inputs!$B$73<=0,0,ROUNDUP(C11*Inputs!$B$71/MAX(C13,0.0001),0)) -> 24
A27: Reading it: at these inputs a shop inspection costs a few tens of cents to deliver, so either pricing model clears 90%+ gross margin. The real costs of this product are sales and onboarding (not COGS) and the accuracy of the detection model — if a Pro-class model or a second pass per photo is needed, multiply the AI line accordingly on Inputs. Per-inspection break-even for option A is 0 because every inspection is gross-margin positive; option B shows how many inspections a subscription must cover before COGS is paid.
